Workbook

Sheet Index
A1: VoidYield 2 — Balance Sheet
A2: Source: GAME.md (Part I) — extracted 2026-04-29 after Round 12 (R72–R77)
A3: All values are placeholders for Stage 3 playtest tuning. Edit blue cells; black cells recalculate.
A5: Sheet | B5: Contents
A6: Tier_Ladder | B6: 8 named tiers (T0 Wildcatter → T7 System Corporation), gate conditions, headline capabilities
A7: Resources | B7: All 27 resources T0–T3: tier, class, cargo, Earth buy/sell prices + computed margin/margin%
A8: Recipes | B8: All 31 recipes T0–T3: cycle time, inputs, outputs, derived rate/min, value-add/cycle
A9: Adjacency_Pairs | B9: All 22 pair-type bonuses T0–T3 (R72): placer + pair + bonus magnitude
A10: People_Costs | B10: All buildings + people_cost (R73). Sanity-check: total starter T0 chain cost vs. 8-person crew
A11: Pop_Tiers | B11: Six pop tiers + multipliers + settle-in windows + continuous needs + growth-tier bundles
A12: Storage_Caps | B12: Silo/Tank/Cryo capacities by tier transition
A13: Fuel_Costs | B13: Per-route base fuel costs (R74); window multipliers; computed leg costs by hull
A14: Ships | B14: 6 hull catalog T0–T2 (capacity, speed, fuel/route multiplier, Earth buy)
A15: Tier_Gates | B15: Primary + alternate fulfillment for T0→T1 through T3→T4 (R76)
A16: Action_Durations | B16: Build/transit/cycle times across the game
A17: Earth_Prefab_Kits | B17: T1–T3 Earth-bought prefab kits (1-of-1 per tier)
A20: Color Legend
A21: Blue cells | B21: Hardcoded inputs from GAME.md — change to test what-if scenarios.
A22: Black cells | B22: Computed formulas — recalculate when inputs change.
A23: Green cells | B23: Cross-sheet links — pull values from other sheets.

Sheet Tier_Ladder
A1: Tier | B1: Name | C1: Region Unlocked | D1: Gate to Next Tier | E1: Headline New Capability
A2: T0 | B2: Wildcatter | C2: Earth orbit + 1 NEA | D2: Sell N metals to Earth | E2: Ship surveying, basic mining
A3: T1 | B3: Lunar Foothold | C3: Moon orbit + lunar surface site | D3: First habitat reaches Pop 50 | E3: First colony, life-support imports
A4: T2 | B4: NEA Industry | C4: NEA cluster (3–5 asteroids) | D4: Local oxygen + water production | E4: Tankers, fluid/gas cargo class
A5: T3 | B5: Cislunar Network | C5: Rare-trace NEAs (~15–20% of NEAs) | D5: Mars shipyard built; Networked-tier colony | E5: Maintain-stock + surplus-export rules; Networked pop tier
A6: T4 | B6: Martian Reach | C6: Mars orbit + Phobos/Deimos | D6: (deferred to T4 drill — Pending #39) | E6: Local shipbuilding, advanced alloys
A7: T5 | B7: Belt Operations | C7: Main belt mining hub | D7: 3 tier-3 colonies sustaining | E7: Bulk haulers, advanced refining
A8: T6 | B8: Jovian Frontier | C8: Jovian moons (Europa/Ganymede focus) | D8: Helium-3 / heavy isotope chain | E8: Long-range drives, ice giants
A9: T7 | B9: System Corporation | C9: Saturn + outer system probes | D9: Endgame milestone bundle (5–10h destination) | E9: Prestige unlock
A11: Note: gate conditions are 'content gates, not paywalls' — every gate is something the player produces or builds.

Sheet Resources
A1: # | B1: Resource | C1: Tier | D1: Class | E1: Cargo | F1: Earth Buy | G1: Earth Sell | H1: Margin (Buy-Sell) | I1: Margin % | J1: Notes
A2: 1 | B2: Iron Ore | C2: T0 | D2: Raw | E2: Solid | F2: 3 | G2: 1 | H2: =F2-G2 | I2: =IFERROR((F2-G2)/F2,0)
A3: 2 | B3: Water Ice | C3: T0 | D3: Raw | E3: Solid | F3: 4 | G3: 2 | H3: =F3-G3 | I3: =IFERROR((F3-G3)/F3,0)
A4: 3 | B4: Refined Metal | C4: T0 | D4: Intermediate | E4: Solid | F4: 18 | G4: 12 | H4: =F4-G4 | I4: =IFERROR((F4-G4)/F4,0)
A5: 4 | B5: Hydrogen Fuel | C5: T0 | D5: Intermediate | E5: Fluid/Gas | F5: 8 | G5: 5 | H5: =F5-G5 | I5: =IFERROR((F5-G5)/F5,0) | J5: v1 fuel through T2
A6: 5 | B6: Oxygen | C6: T0* | D6: Intermediate | E6: Fluid/Gas | F6: 6 | G6: 3 | H6: =F6-G6 | I6: =IFERROR((F6-G6)/F6,0) | J6: Electrolysis byproduct; load-bearing at T1
A7: 6 | B7: Lunar Regolith | C7: T1 | D7: Raw | E7: Solid | G7: 2 | H7: — | I7: — | J7: No Earth buy
A8: 7 | B8: Aluminum | C8: T1 | D8: Intermediate | E8: Solid | F8: 22 | G8: 15 | H8: =F8-G8 | I8: =IFERROR((F8-G8)/F8,0)
A9: 8 | B9: Construction Materials | C9: T1 | D9: Finished | E9: Solid | F9: 60 | G9: 45 | H9: =F9-G9 | I9: =IFERROR((F9-G9)/F9,0)
A10: 9 | B10: Food Pack | C10: T1 | D10: Finished | E10: Solid | F10: 25 | G10: 18 | H10: =F10-G10 | I10: =IFERROR((F10-G10)/F10,0)
A11: 10 | B11: Habitat Module | C11: T1 | D11: Finished | E11: Solid | F11: 180 | G11: 130 | H11: =F11-G11 | I11: =IFERROR((F11-G11)/F11,0) | J11: Earth Prefab Kit at T1
A12: 11 | B12: Nickel Ore | C12: T2 | D12: Raw | E12: Solid | F12: 5 | G12: 2 | H12: =F12-G12 | I12: =IFERROR((F12-G12)/F12,0)
A13: 12 | B13: Carbonaceous Ore | C13: T2 | D13: Raw | E13: Solid | F13: 4 | G13: 2 | H13: =F13-G13 | I13: =IFERROR((F13-G13)/F13,0)
A14: 13 | B14: Silicates | C14: T2 | D14: Raw | E14: Solid | F14: 4 | G14: 2 | H14: =F14-G14 | I14: =IFERROR((F14-G14)/F14,0)
A15: 14 | B15: Pressure Valves | C15: T2 | D15: Finished | E15: Solid | F15: 90 | G15: 65 | H15: =F15-G15 | I15: =IFERROR((F15-G15)/F15,0)
A16: 15 | B16: Habitat Glass | C16: T2 | D16: Finished | E16: Solid | F16: 75 | G16: 55 | H16: =F16-G16 | I16: =IFERROR((F16-G16)/F16,0)
A17: 16 | B17: Carbon Mesh | C17: T2 | D17: Intermediate | E17: Solid | F17: 40 | G17: 28 | H17: =F17-G17 | I17: =IFERROR((F17-G17)/F17,0)
A18: 17 | B18: Textiles | C18: T2 | D18: Finished | E18: Solid | F18: 70 | G18: 50 | H18: =F18-G18 | I18: =IFERROR((F18-G18)/F18,0)
A19: 18 | B19: Furnishings | C19: T2 | D19: Finished | E19: Solid | F19: 110 | G19: 80 | H19: =F19-G19 | I19: =IFERROR((F19-G19)/F19,0)
A20: 19 | B20: Spirits | C20: T2 | D20: Finished | E20: Fluid/Gas | F20: 95 | G20: 70 | H20: =F20-G20 | I20: =IFERROR((F20-G20)/F20,0)
A21: 20 | B21: Hydroponic Yield | C21: T2 | D21: Intermediate | E21: Solid | G21: 12 | H21: — | I21: — | J21: No Earth buy
A22: 21 | B22: Rare Trace Elements | C22: T3 | D22: Raw | E22: Solid | F22: 30 | G22: 18 | H22: =F22-G22 | I22: =IFERROR((F22-G22)/F22,0) | J22: Rare-trace NEAs only (~15–20%)
A23: 22 | B23: Ammonia | C23: T3 | D23: Raw | E23: Fluid/Gas | F23: 12 | G23: 7 | H23: =F23-G23 | I23: =IFERROR((F23-G23)/F23,0) | J23: Earth buy only until T6
A24: 23 | B24: Logic Boards | C24: T3 | D24: Intermediate | E24: Solid | F24: 80 | G24: 55 | H24: =F24-G24 | I24: =IFERROR((F24-G24)/F24,0)
A25: 24 | B25: Refined Hydrogen | C25: T3 | D25: Intermediate | E25: Fluid/Gas | F25: 25 | G25: 16 | H25: =F25-G25 | I25: =IFERROR((F25-G25)/F25,0) | J25: T3+ advanced-hull fuel grade
A26: 25 | B26: Comms Module | C26: T3 | D26: Finished | E26: Solid | F26: 250 | G26: 180 | H26: =F26-G26 | I26: =IFERROR((F26-G26)/F26,0)
A27: 26 | B27: Sensor Array | C27: T3 | D27: Finished | E27: Solid | F27: 220 | G27: 160 | H27: =F27-G27 | I27: =IFERROR((F27-G27)/F27,0)
A28: 27 | B28: Maintenance Kit | C28: T3 | D28: Finished | E28: Solid | F28: 180 | G28: 130 | H28: =F28-G28 | I28: =IFERROR((F28-G28)/F28,0)
A30: Margin = Earth Buy − Earth Sell (the spread Earth captures). Margin % = margin / Buy.
A31: * Oxygen: T0 byproduct only at low margin; load-bearing for life support from T1 onward.

Sheet Recipes
A1: Tier | B1: Building | C1: Cycle (s) | D1: Inputs | E1: Outputs | F1: Output Qty | G1: Output Resource | H1: Cycles/min | I1: Output rate/min | J1: Output sell price (Earth) | K1: Output value/min ($) | L1: Notes
A2: T0 | B2: Small Mine | C2: 30 | D2: — | E2: 10 Iron Ore | F2: 10 | G2: Iron Ore | H2: =60/C2 | I2: =F2*60/C2 | J2: =Resources!G2 | K2: =I2*J2
A3: T0 | B3: Ice Mine | C3: 40 | D3: — | E3: 8 Water Ice | F3: 8 | G3: Water Ice | H3: =60/C3 | I3: =F3*60/C3 | J3: =Resources!G3 | K3: =I3*J3
A4: T0 | B4: Smelter | C4: 45 | D4: 5 Iron Ore | E4: 2 Refined Metal | F4: 2 | G4: Refined Metal | H4: =60/C4 | I4: =F4*60/C4 | J4: =Resources!G4 | K4: =I4*J4 | L4: Signature pair: +30% near Mine
A5: T0 | B5: Electrolyzer | C5: 60 | D5: 4 Water Ice | E5: 3 Hydrogen Fuel + 1 Oxygen | F5: 3 | G5: Hydrogen Fuel | H5: =60/C5 | I5: =F5*60/C5 | J5: =Resources!G5 | K5: =I5*J5 | L5: Output also produces 1 Oxygen
A6: T0 | B6: Probe Bay | D6: — | E6: passive surveying | H6: — | I6: — | J6: — | K6: — | L6: Not a recipe; survey time = 4 min
A7: T0 | B7: Silo | D7: — | E7: +300 solids capacity | H7: — | I7: — | J7: — | K7: — | L7: Storage, neutral
A8: T0 | B8: Tank | D8: — | E8: +180 fluids/gases capacity | H8: — | I8: — | J8: — | K8: — | L8: Storage, neutral
A9: T1 | B9: Lunar Surface Mine | C9: 50 | D9: — | E9: 6 Lunar Regolith | F9: 6 | G9: Lunar Regolith | H9: =60/C9 | I9: =F9*60/C9 | J9: =Resources!G7 | K9: =I9*J9
A10: T1 | B10: Refinery (Aluminum) | C10: 70 | D10: 3 Lunar Regolith | E10: 2 Aluminum | F10: 2 | G10: Aluminum | H10: =60/C10 | I10: =F10*60/C10 | J10: =Resources!G8 | K10: =I10*J10 | L10: Signature: +30% near Lunar Surface Mine
A11: T1 | B11: Construction Yard | C11: 90 | D11: 2 Refined Metal + 2 Aluminum | E11: 1 Construction Materials | F11: 1 | G11: Construction Materials | H11: =60/C11 | I11: =F11*60/C11 | J11: =Resources!G9 | K11: =I11*J11
A12: T1 | B12: Habitat Assembler | C12: 480 | D12: 6 Construction Materials | E12: 1 Habitat Module | F12: 1 | G12: Habitat Module | H12: =60/C12 | I12: =F12*60/C12 | J12: =Resources!G11 | K12: =I12*J12 | L12: 8 min/cycle — slow on purpose
A13: T1 | B13: Greenhouse (small) | C13: 60 | D13: 2 Water Ice | E13: 2 Food Pack | F13: 2 | G13: Food Pack | H13: =60/C13 | I13: =F13*60/C13 | J13: =Resources!G10 | K13: =I13*J13
A14: T1 | B14: Life Support — Water | D14: 1 Water Ice / pop / 8 min | E14: — | H14: — | I14: — | J14: — | K14: — | L14: Continuous draw
A15: T1 | B15: Life Support — Oxygen | D15: 1 Oxygen / pop / 6 min | E15: — | H15: — | I15: — | J15: — | K15: — | L15: Continuous draw
A16: T1 | B16: Life Support — Food | D16: 1 Food Pack / pop / 12 min | E16: — | H16: — | I16: — | J16: — | K16: — | L16: Continuous draw
A17: T2 | B17: NEA Mine (Nickel) | C17: 45 | D17: — | E17: 6 Nickel Ore | F17: 6 | G17: Nickel Ore | H17: =60/C17 | I17: =F17*60/C17 | J17: =Resources!G12 | K17: =I17*J17
A18: T2 | B18: NEA Mine (Carbon) | C18: 45 | D18: — | E18: 6 Carbonaceous Ore | F18: 6 | G18: Carbonaceous Ore | H18: =60/C18 | I18: =F18*60/C18 | J18: =Resources!G13 | K18: =I18*J18
A19: T2 | B19: NEA Mine (Silicates) | C19: 50 | D19: — | E19: 7 Silicates | F19: 7 | G19: Silicates | H19: =60/C19 | I19: =F19*60/C19 | J19: =Resources!G14 | K19: =I19*J19
A20: T2 | B20: Hydroponics Bay | C20: 60 | D20: 2 Water Ice | E20: 2 Hydroponic Yield | F20: 2 | G20: Hydroponic Yield | H20: =60/C20 | I20: =F20*60/C20 | J20: =Resources!G21 | K20: =I20*J20
A21: T2 | B21: Hydroponic Greenhouse | C21: 45 | D21: 2 Hydroponic Yield | E21: 4 Food Pack | F21: 4 | G21: Food Pack | H21: =60/C21 | I21: =F21*60/C21 | J21: =Resources!G10 | K21: =I21*J21 | L21: T2 upgrade replaces small greenhouse
A22: T2 | B22: Glass Furnace | C22: 90 | D22: 4 Silicates + 1 Aluminum | E22: 2 Habitat Glass | F22: 2 | G22: Habitat Glass | H22: =60/C22 | I22: =F22*60/C22 | J22: =Resources!G16 | K22: =I22*J22 | L22: Signature: +30% near Silicates Mine
A23: T2 | B23: Carbon Mill | C23: 75 | D23: 3 Carbonaceous Ore + 1 Refined Metal | E23: 2 Carbon Mesh | F23: 2 | G23: Carbon Mesh | H23: =60/C23 | I23: =F23*60/C23 | J23: =Resources!G17 | K23: =I23*J23 | L23: Signature: +30% near Carbon Mine
A24: T2 | B24: Pressure-Valve Forge | C24: 120 | D24: 2 Refined Metal + 1 Nickel Ore | E24: 1 Pressure Valves | F24: 1 | G24: Pressure Valves | H24: =60/C24 | I24: =F24*60/C24 | J24: =Resources!G15 | K24: =I24*J24
A25: T2 | B25: Textile Mill | C25: 100 | D25: 2 Carbon Mesh + 1 Hydroponic Yield | E25: 2 Textiles | F25: 2 | G25: Textiles | H25: =60/C25 | I25: =F25*60/C25 | J25: =Resources!G18 | K25: =I25*J25
A26: T2 | B26: Furnishings Workshop | C26: 150 | D26: 1 Aluminum + 1 Carbon Mesh + 1 Textiles | E26: 1 Furnishings | F26: 1 | G26: Furnishings | H26: =60/C26 | I26: =F26*60/C26 | J26: =Resources!G19 | K26: =I26*J26
A27: T2 | B27: Distillery | C27: 180 | D27: 3 Hydroponic Yield + 1 Water Ice | E27: 1 Spirits | F27: 1 | G27: Spirits | H27: =60/C27 | I27: =F27*60/C27 | J27: =Resources!G20 | K27: =I27*J27
A28: T3 | B28: Trace Mine | C28: 90 | D28: — | E28: 2 Rare Trace Elements | F28: 2 | G28: Rare Trace Elements | H28: =60/C28 | I28: =F28*60/C28 | J28: =Resources!G22 | K28: =I28*J28 | L28: Rare-trace NEAs only
A29: T3 | B29: Logic Foundry | C29: 120 | D29: 1 Refined Metal + 2 Rare Trace Elements + 1 Aluminum | E29: 2 Logic Boards | F29: 2 | G29: Logic Boards | H29: =60/C29 | I29: =F29*60/C29 | J29: =Resources!G24 | K29: =I29*J29 | L29: Signature: +30% near Trace Mine
A30: T3 | B30: Comms Workshop | C30: 100 | D30: 2 Logic Boards + 1 Aluminum | E30: 1 Comms Module | F30: 1 | G30: Comms Module | H30: =60/C30 | I30: =F30*60/C30 | J30: =Resources!G26 | K30: =I30*J30
A31: T3 | B31: Sensor Lab | C31: 110 | D31: 2 Logic Boards + 1 Carbon Mesh | E31: 1 Sensor Array | F31: 1 | G31: Sensor Array | H31: =60/C31 | I31: =F31*60/C31 | J31: =Resources!G27 | K31: =I31*J31
A32: T3 | B32: Maintenance Shop | C32: 90 | D32: 1 Pressure Valves + 1 Aluminum | E32: 1 Maintenance Kit | F32: 1 | G32: Maintenance Kit | H32: =60/C32 | I32: =F32*60/C32 | J32: =Resources!G28 | K32: =I32*J32
A33: T3 | B33: Catalytic Reactor | C33: 120 | D33: 2 Ammonia + 1 Hydrogen Fuel | E33: 2 Refined Hydrogen | F33: 2 | G33: Refined Hydrogen | H33: =60/C33 | I33: =F33*60/C33 | J33: =Resources!G25 | K33: =I33*J33
A34: T3 | B34: Automation Hub | D34: — | E34: hosts 4 automation rules | H34: — | I34: — | J34: — | K34: — | L34: Required for any automation at body
A36: Cycles/min = 60 / cycle_s. Output rate/min = output_qty × 60 / cycle_s.
A37: Output value/min uses Earth Sell price as a unit reference — the actual route economics depend on hull, leg, and fuel costs (see Fuel_Costs / Ships).
A38: Recipes for Electrolyzer also produce 1 Oxygen byproduct per cycle — not modeled in the headline rate.

Sheet Adjacency_Pairs
A1: Tier Band | B1: Placer | C1: Pairs With | D1: Bonus | E1: Notes
A2: T0 | B2: Smelter | C2: Small Mine | D2: 0.3 | E2: Signature T0 pair; FTUE compare-moment
A3: T1 | B3: Smelter | C3: Lunar Surface Mine | D3: 0.25 | E3: T1 variant
A4: T0 | B4: Electrolyzer | C4: Ice Mine | D4: 0.25 | E4: Signature T0 fluid pair
A5: T1 | B5: Refinery (Aluminum) | C5: Lunar Surface Mine | D5: 0.3 | E5: Signature T1 pair
A6: T1 | B6: Construction Yard | C6: Refinery (Aluminum) | D6: 0.2 | E6: Mid-chain feed
A7: T1 | B7: Construction Yard | C7: Smelter | D7: 0.2 | E7: Alt feed source
A8: T1 | B8: Habitat Assembler | C8: Construction Yard | D8: 0.25 | E8: Late-T1 chain capper
A9: T1 | B9: Greenhouse (small) | C9: Ice Mine | D9: 0.2 | E9: Cuts water-feed friction
A10: T2 | B10: Hydroponics Bay | C10: Ice Mine | D10: 0.2 | E10: T2 upgrade path
A11: T2 | B11: Hydroponic Greenhouse | C11: Hydroponics Bay | D11: 0.25 | E11: T2 stack
A12: T2 | B12: Glass Furnace | C12: NEA Mine (Silicates) | D12: 0.3 | E12: Signature T2 pair
A13: T2 | B13: Carbon Mill | C13: NEA Mine (Carbon) | D13: 0.3 | E13: Signature T2 pair
... A23: T3 | B23: Automation Hub | C23: (any building) | D23: 0.1 | E23: On-site staff coordination; deliberately small
A25: Range: 15%–35% (R72). Signature pairs sit at top (30%); standard pairs at 20–25%.
A26: Stacking cap: max 2 pair bonuses per building. Pairs are bidirectional (each side receives the listed bonus).
A27: Storage buildings (Silo / Tank / Cryo Tank) are neutral — don't grant or receive bonuses (R70).
A28: Collaboration radius: default 2 tiles, uniform (R69). Per-building override architecturally supported.

Sheet People_Costs
A1: Tier Band | B1: Building | C1: People Cost
A2: Source | B2: Earth-orbit starter crew (free, T0) | C2: 8
A3: T0 | B3: Small Mine | C3: 2
A4: T0 | B4: Ice Mine | C4: 2
A5: T0 | B5: Smelter | C5: 3
A6: T0 | B6: Electrolyzer | C6: 3
A7: T0 | B7: Probe Bay | C7: 1
A8: T1 | B8: Lunar Surface Mine | C8: 3
A9: T1 | B9: Refinery (Aluminum) | C9: 4
A10: T1 | B10: Construction Yard | C10: 5
A11: T1 | B11: Habitat Assembler | C11: 6
A12: T1 | B12: Greenhouse (small) | C12: 2
A13: T1 | B13: Life Support (Water / Oxygen / Food, each) | C13: 1
... A30: Storage | B30: Silo / Tank / Cryo Tank | C30: 0
A32: People Capacity sources & multipliers
A33: Source | B33: Contribution
A34: Earth-orbit starter | B34: 8 capacity (free, T0)
A35: Each colony | B35: Pop × pop-tier multiplier (see Pop_Tiers)
A37: T0 sanity check
A38: Available capacity | C38: 8
A39: 1 Small Mine + 1 Smelter + 1 Probe Bay | C39: =C3+C5+C7
A40: Reserve | C40: =C38-C39

Sheet Pop_Tiers
A1: Pop Tier | B1: Unlocks At | C1: Multiplier | D1: Settle-in Window | E1: Continuous Needs | F1: Growth-Tier Bundle (one-time) | G1: Sample 32-pop capacity
A2: Survival | B2: T1 (first habitat) | C2: 1 | D2: 5 min | E2: Water, Oxygen, Food Pack | F2: 4 Construction Materials | G2: =32*C2
A3: Settled | B3: T1 (habitat upgraded) | C3: 1.25 | D3: 20 min | E3: (no new continuous needs) | F3: 8 Construction Materials + 2 Habitat Module | G3: =32*C3
A4: Growing | B4: T2 (Glass + Valves available) | C4: 1.5 | D4: 1 h | E4: + Pressure Valves drip (1 / pop / 30 min) | F4: 6 Habitat Glass + 4 Pressure Valves | G4: =32*C4
A5: Comfortable | B5: T2 late | C5: 1.75 | D5: 2 h | E5: + Textiles drip (1 / pop / 60 min) | F5: 8 Textiles + 4 Furnishings | G5: =32*C5
A6: Affluent | B6: T2 endgame | C6: 2 | D6: 4 h | E6: + Spirits drip (1 / pop / 90 min) | F6: 6 Furnishings + 4 Spirits | G6: =32*C6
A7: Networked (T3) | B7: T3 endgame | C7: 2.25 | D7: 8 h | E7: + Comms Module drip (1 / pop / 60 min) + Sensor Array drip (1 / pop / 240 min) | F7: 6 Comms Module + 4 Sensor Array | G7: =32*C7
A9: Settle-in across AFK: progresses while away, capped at one tier transition per AFK return (R67). Window resumes (does not restart).
A10: Sample 32-pop capacity column: a hypothetical 32-population habitat at this tier — convenient ratio check vs. building people-cost totals.

Sheet Storage_Caps
A1: Storage Building | B1: Class | C1: T0 cap | D1: T2 cap | E1: T4 cap | F1: T6 cap | G1: T2/T0 multiplier
A2: Silo | B2: Solids | C2: 300 | D2: 900 | E2: 3000 | F2: 9000 | G2: =D2/C2
A3: Tank | B3: Fluids/Gases | C3: 180 | D3: 540 | E3: 1800 | F3: 5400 | G3: =D3/C3
A4: Cryo Tank | B4: Specialty cold-chain | C4: — | D4: 240 | E4: 800 | F4: 2400 | G4: —
A6: Each storage building takes 1 grid slot. Capacity is per-resource (each Silo holds a single resource at a time, R74).
A7: Auto-upgrade in place at tier transitions (R60) — no demolish/rebuild, no resource loss. Reassign empty storage for $200 (placeholder).

Sheet Fuel_Costs
A1: Leg | B1: Base Fuel
A2: Earth ↔ Moon | B2: 3
A3: Earth ↔ NEA cluster | B3: 5
A4: NEA ↔ Lunar Habitat | B4: 2
A5: Earth ↔ Mars (window-good) | B5: 25
A6: Earth ↔ Mars (window-poor) | B6: 40
A7: Earth ↔ Belt | B7: 60
A8: Earth ↔ Jovian | B8: 140
A10: Window multipliers
A11: Good window | B11: 0.85
A12: Neutral | B12: 1
A13: Poor window | B13: 1.25
A15: Sample: Hauler-1 fuel cost per leg (neutral window)
A16: Leg | B16: Base | C16: Hull mult (Hauler-1) | D16: Window mult | E16: Total fuel
A17: Earth ↔ Moon | B17: =B3 | C17: 1 | D17: =B12 | E17: =B17*C17*D17
A18: Earth ↔ NEA cluster | B18: =B4 | C18: 1 | D18: =B12 | E18: =B18*C18*D18
A19: NEA ↔ Lunar Habitat | B19: =B5 | C19: 1 | D19: =B12 | E19: =B19*C19*D19
A20: Earth ↔ Mars (window-good) | B20: =B6 | C20: 1 | D20: =B12 | E20: =B20*C20*D20
A21: Earth ↔ Mars (window-poor) | B21: =B7 | C21: 1 | D21: =B12 | E21: =B21*C21*D21
A22: Earth ↔ Belt | B22: =B8 | C22: 1 | D22: =B12 | E22: =B22*C22*D22
A23: Earth ↔ Jovian | B23: =B9 | C23: 1 | D23: =B12 | E23: =B23*C23*D23
A25: Fuel deducts from origin body's tank at dispatch. Multi-stop: per-leg deduction at each leg's origin.
A26: Mid-route empty origin → ship strands; recovery: dispatch tanker (or buy Earth-bought Hydrogen Fuel order).

Sheet Ships
A1: Hull | B1: Tier | C1: Family | D1: Solid slots | E1: Fluid slots | F1: Total slots | G1: Speed | H1: Fuel/Route | I1: Earth Buy | J1: $ per slot
A2: Hauler-1 | B2: T0 | C2: Specialized Solid | D2: 30 | E2: 0 | F2: =D2+E2 | G2: 1 | H2: 1 | I2: 3000 | J2: =I2/F2
A3: Mixer-1 | B3: T0 | C3: Combined | D3: 20 | E3: 10 | F3: =D3+E3 | G3: 0.95 | H3: 1.05 | I3: 4200 | J3: =I3/F3
A4: Tanker-1 | B4: T1 | C4: Specialized Fluid | D4: 0 | E4: 25 | F4: =D4+E4 | G4: 0.9 | H4: 1.1 | I4: 4800 | J4: =I4/F4
A5: Hauler-2 | B5: T2 | C5: Specialized Solid | D5: 75 | E5: 0 | F5: =D5+E5 | G5: 1.1 | H5: 1.3 | I5: 9500 | J5: =I5/F5
A6: Tanker-2 | B6: T2 | C6: Specialized Fluid | D6: 0 | E6: 60 | F6: =D6+E6 | G6: 1 | H6: 1.4 | I6: 11500 | J6: =I6/F6
A7: Mixer-2 | B7: T2 | C7: Combined | D7: 45 | E7: 25 | F7: =D7+E7 | G7: 1 | H7: 1.4 | I7: 12500 | J7: =I7/F7
A9: $ per slot = Earth Buy ÷ Total slots — efficiency-vs-investment metric for fleet purchase decisions.
A10: Specialist hulls (probe ships, builders) deferred — at T0–T2 the Probe Bay building handles surveys.
A11: T2 hulls roughly 3× capacity at ~3× cost — meaningful investment, not free upgrade.

Sheet Tier_Gates
A1: Transition | B1: Clause | C1: Theme | D1: Primary Path | E1: Alternate Path
A2: T0 → T1 (Lunar Foothold) | B2: A | C2: Refined output | D2: Sell 200 Refined Metal to Earth | E2: Sell 800 Iron Ore raw to Earth
A3: T0 → T1 (Lunar Foothold) | B3: B | C3: Fuel readiness | D3: Accumulate 50 Hydrogen Fuel reserves at any single body | E3: Sell 80 Hydrogen Fuel cumulatively to Earth
A4: T1 → T2 (NEA Industry) | B4: A | C4: Settlement | D4: First habitat reaches Pop 50 | E4: Maintain Survival tier on 2 distinct habitats simultaneously
A5: T1 → T2 (NEA Industry) | B5: B | C5: Frontier reach | D5: Claim 2 NEA surveys | E5: Claim 1 NEA + 1 lunar surface site
A6: T2 → T3 (Cislunar Network) | B6: A | C6: Local life support | D6: Local oxygen break-even at lunar habitat (no Earth O2 imports for 24h game time) | E6: Ship 200 locally-produced Oxygen to a different body cumulatively
A7: T2 → T3 (Cislunar Network) | B7: B | C7: Pop maturity | D7: Habitat reaches Comfortable pop tier | E7: Growing pop tier on 2 habitats simultaneously
A8: T3 → T4 (Martian Reach) | B8: A | C8: Distributed production | D8: Build first non-Earth shipyard at Mars orbit | E8: Establish Industrial Control Unit production at 2 distinct bodies (T4 placeholder)
A9: T3 → T4 (Martian Reach) | B9: B | C9: Networked colony | D9: Maintain a Networked-tier colony | E9: Maintain Affluent + 2 Comfortable colonies simultaneously
A11: Both clauses must complete (primary OR alternate within each clause). Alternates are equivalent-difficulty-different-approach (R76).
A12: Stage 3 acceptance: 10–25% of runs reach the alternate path (signal it's a real lane, not a curiosity).
A13: T4+ gates remain at named-only level (Pending #39).

Sheet Action_Durations
A1: Action | B1: Duration | C1: Seconds (parsed)
A2: Survey one NEA (T0 probe) | B2: 4 min | C2: 240
A3: Mine cycle (small mine, 1 batch) | B3: 30 s | C3: 30
A4: Smelt cycle | B4: 45 s | C4: 45
A5: Build small habitat | B5: 8 min | C5: 480
A6: Earth → Moon transit (good window) | B6: 6 min | C6: 360
A7: Earth → Mars transit (good window) | B7: 35 min | C7: 2100
A8: Earth → Belt transit | B8: 90 min | C8: 5400
A9: Build T1 ship at Earth shipyard | B9: 12 min | C9: 720
A10: Pop-tier settle-in: Survival | B10: 5 min | C10: 300
A11: Pop-tier settle-in: Settled | B11: 20 min | C11: 1200
A12: Pop-tier settle-in: Growing | B12: 1 h | C12: 3600
A13: Pop-tier settle-in: Comfortable | B13: 2 h | C13: 7200
... A16: AFK catch-up hard cap | B16: 24 h | C16: 86400
A18: Game time : real time = 1:1. Simulation tick = 1 Hz foreground; deterministic catch-up offline.

Sheet Earth_Prefab_Kits
A1: Tier | B1: Kit Name | C1: Cost | D1: Contents | E1: Notes
A2: T1 | B2: Lunar Habitat Kit | C2: (unspec) | D2: 1 Habitat Module (drops directly on Moon) | E2: Bootstraps first habitat before local construction chain
A3: T1 | B3: Lunar Surface Mine Kit | C3: (unspec) | D3: 1 Lunar Surface Mine (drops on Moon) | E3: Bootstraps first local mine
A4: T3 | B4: Cislunar Comms Relay Kit | C4: 28000 | D4: 1 Comms Workshop + 1 Automation Hub | E4: Bootstraps automation on first non-lunar T3 expansion
A5: T3 | B5: Sensor Network Kit | C5: 22000 | D5: 1 Sensor Lab + 2 Maintenance Shops | E5: Bootstraps fleet maintenance scaling
A6: T4 | B6: Mars Foothold Kit | C6: (unspec) | D6: (deferred to T4 drill) | E6: Pending #39
A8: Hand-authored, 1-of-1 per kit per tier (R37). Each kit = a tier-up payoff moment.
A9: Total catalog target: ~10–14 kits across T1–T6 (Content Targets).

Sheet T1_T2_Chain_Math
A1: T1–T2 Math Drill: 60-pop Comfortable Lunar Habitat
A2: Target: validate that placeholder numbers can sustain a Comfortable colony on a 7×7 lunar grid (~25–49 slots) within People Capacity at this tier.
A3: Edit blue inputs to test sensitivity. Black formulas update; the slack readouts at the bottom flag bottlenecks.
A5: 1. Scenario Inputs
A6: Population | B6: 60
A7: Pop tier | B7: Comfortable
A8: People Capacity multiplier | B8: 1.75
A9: People Capacity available | B9: =B6*B8 | C9: (Pop × multiplier; Earth-orbit starter +8 not included — single-colony view)
A10: Grid slots (assume 7×7 lunar habitat, mid-roll) | B10: 49
A11: Reserved for habitat life support buildings (Water/O2/Food) | B11: 3
A12: Reserved for storage (Silos + Tank) | B12: 4
A13: Slots available for production | B13: =B10-B11-B12
A15: 2. Continuous Per-Pop Demand → Total Rate Needed
A16: Need | B16: Spec (per pop) | C16: Per-pop /min | D16: Total /min @ 60 pop | H16: Notes
A17: Water Ice | B17: 1 / pop / 8 min | C17: 0.125 | D17: =$B$6*C17 | H17: Life Support — Water
A18: Oxygen | B18: 1 / pop / 6 min | C18: 0.16666667 | D18: =$B$6*C18 | H18: Life Support — Oxygen
A19: Food Pack | B19: 1 / pop / 12 min | C19: 0.083333333 | D19: =$B$6*C19 | H19: Life Support — Food
A20: Pressure Valves | B20: 1 / pop / 30 min (Growing tier+) | C20: 0.033333333 | D20: =$B$6*C20 | H20: Drip
A21: Textiles | B21: 1 / pop / 60 min (Comfortable tier+) | C21: 0.016666667 | D21: =$B$6*C21 | H21: Drip
A24: 3. Building Throughput → Buildings Required (ceiling)
A25: Building | B25: Cycle (s) | C25: Output qty/cycle | D25: Output rate/min | E25: Demand /min | F25: Buildings needed | G25: People per | H25: Total people
A26: Ice Mine | B26: 40 | C26: 8 | D26: =C26*60/B26 | E26: =D17 | F26: =ROUNDUP(E26/D26,0) | G26: 2 | H26: =F26*G26
A27: Electrolyzer (for Oxygen) | B27: 60 | C27: 1 | D27: =C27*60/B27 | E27: =D18 | F27: =ROUNDUP(E27/D27,0) | G27: 3 | H27: =F27*G27
A28: Hydroponic Greenhouse (T2 upgrade) | B28: 45 | C28: 4 | D28: =C28*60/B28 | E28: =D19 | F28: =ROUNDUP(E28/D28,0) | G28: 3 | H28: =F28*G28
A29: Hydroponics Bay (input to Hydro Greenhouse) | B29: 60 | C29: 2 | D29: =C29*60/B29 | E29: =2*60/B28*F28 | F29: =ROUNDUP(E29/D29,0) | G29: 3 | H29: =F29*G29
A30: Pressure-Valve Forge | B30: 120 | C30: 1 | D30: =C30*60/B30 | E30: =D20 | F30: =ROUNDUP(E30/D30,0) | G30: 5 | H30: =F30*G30
A31: Textile Mill | B31: 100 | C31: 2 | D31: =C31*60/B31 | E31: =D21 | F31: =ROUNDUP(E31/D31,0) | G31: 4 | H31: =F31*G31
A33: 4. Upstream feed required (raw + intermediate)
A34: Building | B34: Cycle (s) | C34: Output qty/cycle | D34: Output rate/min | E34: Demand /min | F34: Buildings needed | G34: People per | H34: Total people
A35: Refined Metal needed (for PV Forges) | B35: — | C35: — | D35: — | E35: =2*60/B30*F30
A36: Smelter (5 Iron Ore → 2 Refined Metal) | B36: 45 | C36: 2 | D36: =C36*60/B36 | E36: =E35 | F36: =ROUNDUP(E36/D36,0) | G36: 3 | H36: =F36*G36
A37: Iron Ore needed (for Smelters) | B37: — | C37: — | D37: — | E37: =5*60/B36*F36
A38: Small Mine (10 Iron Ore) | B38: 30 | C38: 10 | D38: =C38*60/B38 | F38: =ROUNDUP(E37/D38,0) | G38: 2 | H38: =F38*G38
A39: Nickel Ore needed (for PV Forges) | B39: — | C39: — | D39: — | E39: =1*60/B30*F30
A40: NEA Mine (Nickel) | B40: 45 | C40: 6 | D40: =C40*60/B40 | F40: =ROUNDUP(E39/D40,0) | G40: 3 | H40: =F40*G40
A41: Carbon Mesh needed (for Textile Mills) | B41: — | C41: — | D41: — | E41: =2*60/B31*F31
A42: Carbon Mill (3 Carbon Ore + 1 RM → 2 Carbon Mesh) | B42: 75 | C42: 2 | D42: =C42*60/B42 | E42: =E41 | F42: =ROUNDUP(E42/D42,0) | G42: 4 | H42: =F42*G42
A43: Carbonaceous Ore needed (for Carbon Mill) | B43: — | C43: — | D43: — | E43: =3*60/B42*F42
A44: NEA Mine (Carbon) | B44: 45 | C44: 6 | D44: =C44*60/B44 | F44: =ROUNDUP(E43/D44,0) | G44: 3 | H44: =F44*G44
A46: 5. Roll-up: people-cost and slot-count totals
...
